#VRML_SIM R2023b utf8

EXTERNPROTO "https://raw.githubusercontent.com/cyberbotics/webots/R2023b/projects/objects/backgrounds/protos/TexturedBackground.proto"
EXTERNPROTO "https://raw.githubusercontent.com/cyberbotics/webots/R2023b/projects/objects/backgrounds/protos/TexturedBackgroundLight.proto"
EXTERNPROTO "https://raw.githubusercontent.com/cyberbotics/webots/R2023b/projects/objects/floors/protos/UnevenTerrain.proto"

WorldInfo {
  coordinateSystem "NUE"
}
Viewpoint {
  orientation -0.1327887476933872 0.6885498929699351 0.7129279019487965 3.5616002118204144
  position 3.8745442476009457 4.27775665944309 -0.11243431737090512
}
TexturedBackground {
}
TexturedBackgroundLight {
}
Robot {
  translation 0 3.14 0
  children [
    GPS {
    }
    DEF WL Hinge2Joint {
      jointParameters HingeJointParameters {
        axis 0 1 0
        anchor 0.045 0.025 -0.0505
      }
      jointParameters2 JointParameters {
      }
      device [
        Brake {
          name "steer_left_brake"
        }
        RotationalMotor {
          name "steer_left_motor"
        }
      ]
      device2 [
        RotationalMotor {
          name "front_left_motor"
        }
      ]
      endPoint Solid {
        translation 0.045 0.025 -0.0505
        rotation 0.999999999983147 -3.4266252157964163e-10 -5.805688597276725e-06 5.305399353369469e-06
        children [
          DEF WL Shape {
            appearance PBRAppearance {
              baseColor 0 0 0
              roughness 1
              metalness 0
            }
            geometry Cylinder {
              height 0.01
              radius 0.025
            }
          }
        ]
        name "solid(3)"
        boundingObject USE WL
        physics Physics {
        }
      }
    }
    InertialUnit {
      name "imu"
    }
    DEF WR Hinge2Joint {
      jointParameters HingeJointParameters {
        axis 0 1 0
        anchor 0.045 0.025 0.0505
      }
      jointParameters2 JointParameters {
      }
      device [
        Brake {
          name "steer_right_brake"
        }
        RotationalMotor {
          name "steer_right_motor"
        }
      ]
      device2 [
        RotationalMotor {
          name "front_right_motor"
        }
      ]
      endPoint Solid {
        translation 0.045 0.025 0.0505
        rotation 0.9999999999965831 0 2.6141619141884517e-06 5.305483057851837e-06
        children [
          DEF Wheel_Right Shape {
            appearance PBRAppearance {
              baseColor 0 0 0
              roughness 1
              metalness 0
            }
            geometry Cylinder {
              height 0.01
              radius 0.025
            }
          }
        ]
        name "solid(2)"
        boundingObject USE Wheel_Right
        physics Physics {
        }
      }
    }
    DEF Windscreen Solid {
      translation 0.066 0.051 0
      children [
        Shape {
          appearance PBRAppearance {
            baseColor 0.08 0.78 1
            roughness 0.2
            metalness 0.8
          }
          geometry Box {
            size 0.03 0.01 0.08
          }
        }
      ]
      name "solid(4)"
    }
    DEF DWL HingeJoint {
      jointParameters HingeJointParameters {
        axis 0 0 1
        anchor -0.045 0.025 -0.0505
      }
      device [
        Brake {
          name "left_brake"
        }
        PositionSensor {
          name "left_pos_sensor"
        }
        RotationalMotor {
          name "left_motor"
        }
      ]
      endPoint Solid {
        translation -0.045 0.025 -0.0505
        rotation -1 4.0906402590549434e-16 3.426246849003184e-10 5.306068952255595e-06
        children [
          DEF Driven_Wheel_Left Shape {
            appearance PBRAppearance {
              baseColor 0 0 0
              roughness 1
              metalness 0
            }
            geometry Cylinder {
              height 0.01
              radius 0.025
            }
          }
        ]
        name "solid(1)"
        boundingObject USE Driven_Wheel_Left
        physics Physics {
        }
      }
    }
    DEF DWR HingeJoint {
      jointParameters HingeJointParameters {
        axis 0 0 1
        anchor -0.045 0.025 0.0505
      }
      device [
        Brake {
          name "right_brake"
        }
        PositionSensor {
          name "right_pos_sensor"
        }
        RotationalMotor {
          name "right_motor"
        }
      ]
      endPoint Solid {
        translation -0.045 0.025 0.05049999999999999
        rotation -1 6.914323211514526e-16 6.1324552303955096e-09 3.6751230222107673e-06
        children [
          DEF Driven_Wheel_Right Shape {
            appearance PBRAppearance {
              baseColor 0 0 0
              roughness 1
              metalness 0
            }
            geometry Cylinder {
              height 0.01
              radius 0.025
            }
          }
        ]
        boundingObject USE Driven_Wheel_Right
        physics Physics {
        }
      }
    }
    DEF Chassis Pose {
      translation 0 0.035 0
      children [
        Shape {
          appearance PBRAppearance {
            baseColor 1 0.78 0.08
            roughness 1
            metalness 0.25
          }
          geometry Box {
            size 0.16 0.04 0.1
          }
        }
      ]
    }
    Accelerometer {
    }
  ]
  boundingObject USE Chassis
  physics Physics {
  }
  controller "kf_controlller_final"
}
UnevenTerrain {
  rotation 1 0 0 -1.5707953071795862
}
