#VRML_SIM R2023b utf8

EXTERNPROTO "https://raw.githubusercontent.com/cyberbotics/webots/R2023b/projects/appearances/protos/ChequeredParquetry.proto"
EXTERNPROTO "https://raw.githubusercontent.com/cyberbotics/webots/R2023b/projects/objects/floors/protos/RectangleArena.proto"
EXTERNPROTO "https://raw.githubusercontent.com/cyberbotics/webots/R2023b/projects/objects/backgrounds/protos/TexturedBackground.proto"
EXTERNPROTO "https://raw.githubusercontent.com/cyberbotics/webots/R2023b/projects/objects/backgrounds/protos/TexturedBackgroundLight.proto"

WorldInfo {
  coordinateSystem "NUE"
}
Viewpoint {
  orientation -0.7595232093493479 0.2875670021870408 -0.5834635496008512 1.6610685723407843
  position -3.2971712576032832 4.041251513119535 -1.170296432878871
}
TexturedBackgroundLight {
}
TexturedBackground {
}
DEF e-puck Robot {
  children [
    Compass {
    }
    Pose {
      translation 0 0.0415 0
      rotation -1 0 0 1.5707963267948966
      children [
        Shape {
          appearance PBRAppearance {
            baseColor 0.0820075 0.364731 0.8
            roughness 1
            metalness 0
          }
          geometry DEF BODY Cylinder {
            height 0.08
            radius 0.045
          }
        }
      ]
    }
    HingeJoint {
      jointParameters HingeJointParameters {
        axis -1 0 0
        anchor 0 0.025 0
      }
      device [
        RotationalMotor {
          name "left wheel motor"
          consumptionFactor 70
        }
        PositionSensor {
          name "left wheel sensor"
        }
      ]
      endPoint Solid {
        translation -0.044999999999959336 0.025 0
        rotation -1 0 0 0
        children [
          DEF WHEEL Pose {
            rotation -0.5776567755050862 -0.5771969549958951 0.5771969549958951 2.0939354039397986
            children [
              Shape {
                appearance PBRAppearance {
                  baseColor 1 0 0
                  roughness 1
                  metalness 0
                }
                geometry Cylinder {
                  height 0.01
                  radius 0.025
                }
              }
            ]
          }
        ]
        name "left wheel"
        boundingObject USE WHEEL
        physics DEF PHYSICS_WHEEL Physics {
          density -1
          mass 0.05
        }
      }
    }
    HingeJoint {
      jointParameters HingeJointParameters {
        axis -1 0 0
        anchor 0 0.025 0
      }
      device [
        RotationalMotor {
          name "right wheel motor"
          consumptionFactor 70
        }
        PositionSensor {
          name "right wheel sensor"
        }
      ]
      endPoint Solid {
        translation 0.04499999840099041 0.025003865829176117 1.089172138303519e-16
        rotation -1 0 0 0
        children [
          USE WHEEL
        ]
        name "right wheel"
        boundingObject USE WHEEL
        physics USE PHYSICS_WHEEL
      }
    }
    DistanceSensor {
      translation 0.02 0.063 -0.042
      rotation 0 1 0 1.1781
      children [
        DEF SENSOR Pose {
          rotation -0.5776567755050862 -0.5771969549958951 0.5771969549958951 2.0939354039397986
          children [
            Shape {
              appearance PBRAppearance {
                baseColor 0.975691 0.981481 0.0252992
                roughness 1
                metalness 0
              }
              geometry Cylinder {
                height 0.004
                radius 0.008
              }
            }
          ]
        }
      ]
      name "ds0"
      lookupTable [
        0 0 0.05
        10 10 0.05
      ]
      type "laser"
      aperture 0.005
    }
    DistanceSensor {
      translation 0.042 0.063 -0.02
      rotation 0 1 0 0.3927
      children [
        USE SENSOR
      ]
      name "ds1"
      lookupTable [
        0 0 0.05
        10 10 0.05
      ]
      type "laser"
      aperture 0.005
    }
    DistanceSensor {
      translation 0.042 0.063 0.02
      rotation 0 1 0 5.8905
      children [
        USE SENSOR
      ]
      name "ds2"
      lookupTable [
        0 0 0.05
        10 10 0.05
      ]
      type "laser"
      aperture 0.005
    }
    DistanceSensor {
      translation 0.02 0.063 0.042
      rotation 0 1 0 5.1051
      children [
        USE SENSOR
      ]
      name "ds3"
      lookupTable [
        0 0 0.05
        10 10 0.05
      ]
      type "laser"
      aperture 0.005
    }
    DistanceSensor {
      translation -0.02 0.063 0.042
      rotation 0 1 0 4.3197
      children [
        USE SENSOR
      ]
      name "ds4"
      lookupTable [
        0 0 0.05
        10 10 0.05
      ]
      aperture 0.005
    }
    DistanceSensor {
      translation -0.042 0.063 0.02
      rotation 0 1 0 3.5343
      children [
        USE SENSOR
      ]
      name "ds5"
      lookupTable [
        0 0 0.05
        10 10 0.05
      ]
      type "laser"
      aperture 0.005
    }
    DistanceSensor {
      translation -0.042 0.063 -0.02
      rotation 0 1 0 2.7489
      children [
        USE SENSOR
      ]
      name "ds6"
      lookupTable [
        0 0 0.05
        10 10 0.05
      ]
      type "laser"
      aperture 0.005
    }
    DistanceSensor {
      translation -0.02 0.063 -0.042
      rotation 0 1 0 1.9635
      children [
        USE SENSOR
      ]
      name "ds7"
      lookupTable [
        0 0 0.05
        10 10 0.05
      ]
      aperture 0.005
    }
    DEF SMILE Pose {
      translation 0 0.025 -0.036
      rotation 3.15961559179624e-06 -1.8335777729622692e-06 0.9999999999933274 1.047197533349439
      children [
        Shape {
          appearance PBRAppearance {
            baseColor 0.721569 0.290196 0.290196
            roughness 1
            metalness 0
          }
          geometry Cylinder {
            height 0.018
            radius 0.009
            subdivision 3
          }
        }
      ]
    }
    Pose {
      rotation 0 1 0 3.14
      children [
        USE SMILE
      ]
    }
  ]
  name "Robot"
  boundingObject Pose {
    translation 0 0.0415 0
    rotation -1 0 0 1.5707963267948966
    children [
      USE BODY
    ]
  }
  physics Physics {
    density -1
    mass 0.5
  }
  controller "pos-prediction"
  supervisor TRUE
  window "pos-prediction"
}
RectangleArena {
  rotation 1 0 0 -1.5707953071795862
  floorSize 3 3
  floorAppearance ChequeredParquetry {
    textureTransform TextureTransform {
    }
  }
  wallHeight 0.3
}
